Workbook

Sheet Report
A1: GITHUB Issues Tracker | M1: Open Issues - Type | S1: Open Issues - Assignee
A2: Date: 17Dec25 @ 10 AM EST | S2: Date: 17Dec25 @ 10 AM EST
A3: Repository | B3: App Name | C3: Open | D3: Closed | E3: Total | F3: % Complete | G3: Change | M3: P1: Task | N3: P2:Bug | O3: P3: Features | P3: Not Specified | S3: Name | T3: Task Count | U3: Tes-BE | V3: Tes-FE | W3: Tes-Pl | X3: Rap | Y3: RapFE | Z3: PSO | AA3: ZWar | AB3: GIT | AC3: ProPul | AD3: AS | AE3: ZWor | AF3: Git RB | AG3: Notes
A4: cloudwarriors-ai/Tesseract | B4: Tesseract - Backend | C4: =COUNTIFS('All Issues'!B:B, "*Tesseract - Backend*", 'All Issues'!E:E, "open") -> 14 | D4: =COUNTIFS('All Issues'!B:B, "*Tesseract - Backend*", 'All Issues'!E:E, "closed") -> 66 | E4: =COUNTIF('All Issues'!B:B, "*Tesseract - Backend*") -> 80 | F4: =D4/$E$4 -> 0.825 | G4: ↔️ | M4: =COUNTIFS('All Issues'!B:B, "*Tesseract - Backend*", 'All Issues'!E:E, "open", 'All Issues'!M:M, "Task") -> 13 | N4: =COUNTIFS('All Issues'!B:B, "*Tesseract - Backend*", 'All Issues'!E:E, "open", 'All Issues'!M:M, "Bug") -> 1 | O4: =COUNTIFS('All Issues'!B:B, "*Tesseract - Backend*", 'All Issues'!E:E, "open", 'All Issues'!M:M, "Feature") -> 0 | P4: =COUNTIFS('All Issues'!B:B, "*Tesseract - Backend*", 'All Issues'!E:E, "open", 'All Issues'!M:M, "Not Specified") -> 0 | S4: Voipin | T4: =COUNTIFS('All Issues'!E:E, "open", 'All Issues'!O:O, "*voipin*") -> 0
A5: cloudwarriors-ai/tesseract-frontend | B5: Tesseract - Frontend | C5: =COUNTIFS('All Issues'!B:B, "*Tesseract - Frontend*", 'All Issues'!E:E, "open") -> 4 | D5: =COUNTIFS('All Issues'!B:B, "*Tesseract - Frontend*", 'All Issues'!E:E, "closed") -> 58 | E5: =COUNTIF('All Issues'!B:B, "*Tesseract - Frontend*") -> 62 | F5: =D5/$E$5 -> 0.93548387 | G5: ↔️ | M5: =COUNTIFS('All Issues'!B:B, "*Tesseract - Frontend*", 'All Issues'!E:E, "open", 'All Issues'!M:M, "Task") -> 1 | N5: =COUNTIFS('All Issues'!B:B, "*Tesseract - Frontend*", 'All Issues'!E:E, "open", 'All Issues'!M:M, "Bug") -> 2 | O5: =COUNTIFS('All Issues'!B:B, "*Tesseract - Frontend*", 'All Issues'!E:E, "open", 'All Issues'!M:M, "Feature") -> 1 | P5: =COUNTIFS('All Issues'!B:B, "*Tesseract - Frontend*", 'All Issues'!E:E, "open", 'All Issues'!M:M, "Not Specified") -> 0 | S5: Chaddacus | T5: =COUNTIFS('All Issues'!E:E, "open", 'All Issues'!O:O, "*Chaddacus*") -> 13 | X5: 1 | Y5: 10 | AD5: 2
A6: cloudwarriors-ai/tesseract-platform | B6: Tessereact Platform | C6: =COUNTIFS('All Issues'!B:B, "*Tesseract Platform*", 'All Issues'!E:E, "open") -> 2 | D6: =COUNTIFS('All Issues'!B:B, "*Tesseract Platform*", 'All Issues'!E:E, "closed") -> 1 | E6: =COUNTIF('All Issues'!B:B, "*Tesseract Platform*") -> 3 | F6: =D6/$E$5 -> 0.016129032 | G6: ⬆️ | M6: =COUNTIFS('All Issues'!B:B, "*Tesseract Platform*", 'All Issues'!E:E, "open", 'All Issues'!M:M, "Task") -> 1 | N6: =COUNTIFS('All Issues'!B:B, "*Tesseract Platform*", 'All Issues'!E:E, "open", 'All Issues'!M:M, "Bug") -> 0 | O6: =COUNTIFS('All Issues'!B:B, "*Tesseract Platform*", 'All Issues'!E:E, "open", 'All Issues'!M:M, "Feature") -> 0 | P6: =COUNTIFS('All Issues'!B:B, "*Tesseract Platform*", 'All Issues'!E:E, "open", 'All Issues'!M:M, "Not Specified") -> 1 | S6: trentcharlton | T6: =COUNTIFS('All Issues'!E:E, "open", 'All Issues'!O:O, "*trentcharlton*") -> 14 | U6: 4 | V6: 1 | W6: 2 | Y6: 7
A7: cloudwarriors-ai/rapture | B7: MACD - Rapture | C7: =COUNTIFS('All Issues'!B:B, "*MACD - Rapture*", 'All Issues'!E:E, "open") -> 2 | D7: =COUNTIFS('All Issues'!B:B, "*MACD - Rapture*", 'All Issues'!E:E, "closed") -> 28 | E7: =COUNTIF('All Issues'!B:B, "*MACD - Rapture*") -> 30 | F7: =D7/E7 -> 0.93333333 | G7: ↔️ | M7: =COUNTIFS('All Issues'!B:B, "*MACD - Rapture*", 'All Issues'!E:E, "open", 'All Issues'!M:M, "Task") -> 0 | N7: =COUNTIFS('All Issues'!B:B, "*MACD - Rapture*", 'All Issues'!E:E, "open", 'All Issues'!M:M, "Bug") -> 1 | O7: =COUNTIFS('All Issues'!B:B, "*MACD - Rapture*", 'All Issues'!E:E, "open", 'All Issues'!M:M, "Feature") -> 1 | P7: =COUNTIFS('All Issues'!B:B, "*MACD - Rapture*", 'All Issues'!E:E, "open", 'All Issues'!M:M, "Not Specified") -> 0 | S7: Jeffrey-Searcy | T7: =COUNTIFS('All Issues'!E:E, "open", 'All Issues'!O:O, "*Jeffrey-Searcy*") -> 6 | U7: 6
A8: cloudwarriors-ai/rapture-frontend | B8: MACD - PSCX Frontend | C8: =COUNTIFS('All Issues'!B:B, "*MACD - PSCX Frontend*", 'All Issues'!E:E, "open") -> 19 | D8: =COUNTIFS('All Issues'!B:B, "*MACD - PSCX Frontend*", 'All Issues'!E:E, "closed") -> 86 | E8: =COUNTIF('All Issues'!B:B, "*MACD - PSCX Frontend*") -> 105 | F8: =D8/E8 -> 0.81904762 | G8: ↔️ | M8: =COUNTIFS('All Issues'!B:B, "*MACD - PSCX Frontend*", 'All Issues'!E:E, "open", 'All Issues'!M:M, "Task") -> 5 | N8: =COUNTIFS('All Issues'!B:B, "*MACD - PSCX Frontend*", 'All Issues'!E:E, "open", 'All Issues'!M:M, "Bug") -> 3 | O8: =COUNTIFS('All Issues'!B:B, "*MACD - PSCX Frontend*", 'All Issues'!E:E, "open", 'All Issues'!M:M, "Feature") -> 11 | P8: =COUNTIFS('All Issues'!B:B, "*MACD - PSCX Frontend*", 'All Issues'!E:E, "open", 'All Issues'!M:M, "Not Specified") -> 0 | S8: jvitato1 | T8: =COUNTIFS('All Issues'!E:E, "open", 'All Issues'!O:O, "*jvitato1*") -> 4 | V8: 1 | W8: 1 | AB8: 2
A9: cloudwarriors-ai/PSO-Quoting-Tool | B9: PSO Tool | C9: =COUNTIFS('All Issues'!B:B, "*PSO Tool*", 'All Issues'!E:E, "open") -> 2 | D9: =COUNTIFS('All Issues'!B:B, "*PSO Tool*", 'All Issues'!E:E, "closed") -> 17 | E9: =COUNTIF('All Issues'!B:B, "*PSO Tool*") -> 19 | F9: =D9/E9 -> 0.89473684 | G9: ⬇️ | M9: =COUNTIFS('All Issues'!B:B, "*PSO Tool*", 'All Issues'!E:E, "open", 'All Issues'!M:M, "Task") -> 1 | N9: =COUNTIFS('All Issues'!B:B, "*PSO Tool*", 'All Issues'!E:E, "open", 'All Issues'!M:M, "Bug") -> 0 | O9: =COUNTIFS('All Issues'!B:B, "*PSO Tool*", 'All Issues'!E:E, "open", 'All Issues'!M:M, "Feature") -> 1 | P9: =COUNTIFS('All Issues'!B:B, "*PSO Tool*", 'All Issues'!E:E, "open", 'All Issues'!M:M, "Not Specified") -> 0 | S9: Matt-Keuning | T9: =COUNTIFS('All Issues'!E:E, "open", 'All Issues'!O:O, "*Matt-Keuning*") -> 14 | U9: 7 | V9: 1 | AA9: 6
A10: cloudwarriors-ai/zoomwarriors_2 | B10: Zoom Warriors | C10: =COUNTIFS('All Issues'!B:B, "*Zoom Warriors*", 'All Issues'!E:E, "open") -> 6 | D10: =COUNTIFS('All Issues'!B:B, "*Zoom Warriors*", 'All Issues'!E:E, "closed") -> 100 | E10: =COUNTIF('All Issues'!B:B, "*Zoom Warriors*") -> 106 | F10: =D10/E10 -> 0.94339623 | G10: ⬆️ | M10: =COUNTIFS('All Issues'!B:B, "*Zoom Warriors*", 'All Issues'!E:E, "open", 'All Issues'!M:M, "Task") -> 1 | N10: =COUNTIFS('All Issues'!B:B, "*Zoom Warriors*", 'All Issues'!E:E, "open", 'All Issues'!M:M, "Bug") -> 0 | O10: =COUNTIFS('All Issues'!B:B, "*Zoom Warriors*", 'All Issues'!E:E, "open", 'All Issues'!M:M, "Feature") -> 5 | P10: =COUNTIFS('All Issues'!B:B, "*Zoom Warriors*", 'All Issues'!E:E, "open", 'All Issues'!M:M, "Not Specified") -> 0 | S10: campbellayers | T10: =COUNTIFS('All Issues'!E:E, "open", 'All Issues'!O:O, "*campbellayers*") -> 4 | Z10: 2 | AB10: 2
A11: cloudwarriors-ai/github_issues_tracker | B11: GitHub Issues Tracker | C11: =COUNTIFS('All Issues'!B:B, "*GitHub Issues Tracker*", 'All Issues'!E:E, "open") -> 2 | D11: =COUNTIFS('All Issues'!B:B, "*GitHub Issues Tracker*", 'All Issues'!E:E, "closed") -> 1 | E11: =COUNTIF('All Issues'!B:B, "*GitHub Issues Tracker*") -> 3 | F11: =D11/E11 -> 0.33333333 | G11: ↔️ | M11: =COUNTIFS('All Issues'!B:B, "*GitHub Issues Tracker*", 'All Issues'!E:E, "open", 'All Issues'!M:M, "Task") -> 0 | N11: =COUNTIFS('All Issues'!B:B, "*GitHub Issues Tracker*", 'All Issues'!E:E, "open", 'All Issues'!M:M, "Bug") -> 0 | O11: =COUNTIFS('All Issues'!B:B, "*GitHub Issues Tracker*", 'All Issues'!E:E, "open", 'All Issues'!M:M, "Feature") -> 2 | P11: =COUNTIFS('All Issues'!B:B, "*GitHub Issues Tracker*", 'All Issues'!E:E, "open", 'All Issues'!M:M, "Not Specified") -> 0 | S11: rebecca-cichy | T11: =COUNTIFS('All Issues'!E:E, "open", 'All Issues'!O:O, "*rebecca-cichy*") -> 7 | V11: 1 | W11: 1 | X11: 2 | Y11: 2 | AC11: 1
A12: cloudwarriors-ai/Project-Pulse | B12: Project Pulse | C12: =COUNTIFS('All Issues'!B:B, "*Project Pulse*", 'All Issues'!E:E, "open") -> 2 | D12: =COUNTIFS('All Issues'!B:B, "*Project Pulse*", 'All Issues'!E:E, "closed") -> 0 | E12: =COUNTIF('All Issues'!B:B, "*Project Pulse*") -> 2 | F12: =D12/E12 -> 0 | G12: ↔️ | M12: =COUNTIFS('All Issues'!B:B, "*Project Pulse*", 'All Issues'!E:E, "open", 'All Issues'!M:M, "Task") -> 1 | N12: =COUNTIFS('All Issues'!B:B, "*Project Pulse*", 'All Issues'!E:E, "open", 'All Issues'!M:M, "Bug") -> 0 | O12: =COUNTIFS('All Issues'!B:B, "*Project Pulse*", 'All Issues'!E:E, "open", 'All Issues'!M:M, "Feature") -> 1 | P12: =COUNTIFS('All Issues'!B:B, "*Project Pulse*", 'All Issues'!E:E, "open", 'All Issues'!M:M, "Not Specified") -> 0 | S12: DsuarezCW | T12: =COUNTIFS('All Issues'!E:E, "open", 'All Issues'!O:O, "*DsuarezCW*") -> 2 | AA12: 2
A13: cloudwarriors-ai/automation-station | B13: Automation Station | C13: =COUNTIFS('All Issues'!B:B, "*Automation Station*", 'All Issues'!E:E, "open") -> 2 | D13: =COUNTIFS('All Issues'!B:B, "*Automation Station*", 'All Issues'!E:E, "closed") -> 18 | E13: =COUNTIF('All Issues'!B:B, "*Automation Station*") -> 20 | F13: =D13/E13 -> 0.9 | G13: ↔️ | M13: =COUNTIFS('All Issues'!B:B, "*Automation Station*", 'All Issues'!E:E, "open", 'All Issues'!M:M, "Task") -> 0 | N13: =COUNTIFS('All Issues'!B:B, "*Automation Station*", 'All Issues'!E:E, "open", 'All Issues'!M:M, "Bug") -> 0 | O13: =COUNTIFS('All Issues'!B:B, "*Automation Station*", 'All Issues'!E:E, "open", 'All Issues'!M:M, "Feature") -> 2 | P13: =COUNTIFS('All Issues'!B:B, "*Automation Station*", 'All Issues'!E:E, "open", 'All Issues'!M:M, "Not Specified") -> 0 | S13: JStab7 | T13: =COUNTIFS('All Issues'!E:E, "open", 'All Issues'!O:O, "*JStab7*") -> 1 | AC13: 1
A14: cloudwarriors-ai/codename_wad | B14: Zoom Workbook | C14: =COUNTIFS('All Issues'!B:B, "*Zoom Workbook*", 'All Issues'!E:E, "open") -> 12 | D14: =COUNTIFS('All Issues'!B:B, "*Zoom Workbook*", 'All Issues'!E:E, "closed") -> 58 | E14: =COUNTIF('All Issues'!B:B, "*Zoom Workbook*") -> 70 | F14: =D14/E14 -> 0.82857143 | G14: ↔️ | M14: =COUNTIFS('All Issues'!B:B, "*Zoom Workbook*", 'All Issues'!E:E, "open", 'All Issues'!M:M, "Task") -> 5 | N14: =COUNTIFS('All Issues'!B:B, "*Zoom Workbook*", 'All Issues'!E:E, "open", 'All Issues'!M:M, "Bug") -> 0 | O14: =COUNTIFS('All Issues'!B:B, "*Zoom Workbook*", 'All Issues'!E:E, "open", 'All Issues'!M:M, "Feature") -> 7 | P14: =COUNTIFS('All Issues'!B:B, "*Zoom Workbook*", 'All Issues'!E:E, "open", 'All Issues'!M:M, "Not Specified") -> 0
A15: cloudwarriors-ai/github_review_build_test | B15: GitHub Review Build | C15: =COUNTIFS('All Issues'!B:B, "*GitHub Review Build*", 'All Issues'!E:E, "open") -> 16 | D15: =COUNTIFS('All Issues'!B:B, "*GitHub Review Build*", 'All Issues'!E:E, "closed") -> 0 | E15: =COUNTIF('All Issues'!B:B, "*GitHub Review Build*") -> 16 | F15: =D15/E15 -> 0 | G15: ↔️ | M15: =COUNTIFS('All Issues'!B:B, "*GitHub Review Build*", 'All Issues'!E:E, "open", 'All Issues'!M:M, "Task") -> 0 | N15: =COUNTIFS('All Issues'!B:B, "*GitHub Review Build*", 'All Issues'!E:E, "open", 'All Issues'!M:M, "Bug") -> 0 | O15: =COUNTIFS('All Issues'!B:B, "*GitHub Review Build*", 'All Issues'!E:E, "open", 'All Issues'!M:M, "Feature") -> 0 | P15: =COUNTIFS('All Issues'!B:B, "*GitHub Review Build*", 'All Issues'!E:E, "open", 'All Issues'!M:M, "Not Specified") -> 16 | S15: TOTALS | T15: =SUM(T4:T14) -> 65 | U15: =SUM(U4:U14) -> 17 | V15: =SUM(V4:V14) -> 4 | W15: =SUM(W4:W14) -> 4 | X15: =SUM(X4:X14) -> 3 | Y15: =SUM(Y4:Y14) -> 19 | Z15: =SUM(Z4:Z14) -> 2 | AA15: =SUM(AA4:AA14) -> 8 | ... AF15: =SUM(AF4:AF14) -> 0
C19: ⬆️ | D19: ↔️ | E19: ⬇️ | F19: FILL IN
C20: *Red Items require Manual Changes
A23: Date: 10Dec25 @ 6 AM EST | S23: Date: 10Dec25 @ 6 AM EST
A24: Repository | B24: App Name | C24: Open | D24: Closed | E24: Total | F24: % Complete | G24: Change | M24: P1: Task | N24: P2:Bug | O24: P3: Features | P24: Not Specified | S24: Name | T24: Task Count | U24: Tes-BE | V24: Tes-FE | W24: Tes-Pl | X24: Rap | Y24: RapFE | Z24: PSO | AA24: ZWar | AB24: GIT | AC24: AS | AD24: ZWor | AE24: Git RB | AF24: Chad | AG24: Supp | AH24: Notes
A25: cloudwarriors-ai/Tesseract | B25: Tesseract - Backend | C25: 14 | D25: 66 | E25: 80 | F25: 0.825 | G25: ↔️ | M25: 13 | N25: 1 | O25: 0 | P25: 0 | S25: Voipin | T25: 0
A26: cloudwarriors-ai/tesseract-frontend | B26: Tesseract - Frontend | C26: 4 | D26: 58 | E26: 62 | F26: 0.93548387 | G26: ↔️ | M26: 1 | N26: 2 | O26: 1 | P26: 0 | S26: Chaddacus | T26: 13 | X26: 1 | Y26: 10 | AC26: 2
A27: cloudwarriors-ai/tesseract-platform | B27: Tessereact Platform | C27: 2 | D27: 0 | E27: 2 | F27: 0 | G27: ↔️ | M27: 1 | N27: 1 | O27: 0 | P27: 0 | S27: trentcharlton | T27: 13 | U27: 4 | V27: 1 | W27: 1 | Y27: 7
A28: cloudwarriors-ai/rapture | B28: MACD - Rapture | C28: 2 | D28: 28 | E28: 30 | F28: 0.93333333 | G28: ↔️ | M28: 0 | N28: 1 | O28: 1 | P28: 0 | S28: Jeffrey-Searcy | T28: 7 | U28: 6 | W28: 1
A29: cloudwarriors-ai/rapture-frontend | B29: MACD - PSCX Frontend | C29: 19 | D29: 86 | E29: 105 | F29: 0.81904762 | G29: ↔️ | M29: 5 | N29: 3 | O29: 11 | P29: 0 | S29: jvitato1 | T29: 3 | V29: 1 | AB29: 2
A30: cloudwarriors-ai/PSO-Quoting-Tool | B30: PSO Tool | C30: 2 | D30: 16 | E30: 18 | F30: 0.88888889 | G30: ↔️ | M30: 2 | N30: 0 | O30: 0 | P30: 0 | S30: Matt-Keuning | T30: 14 | U30: 7 | V30: 1 | AA30: 6
A31: cloudwarriors-ai/zoomwarriors_2 | B31: Zoom Warriors | C31: 6 | D31: 100 | E31: 106 | F31: 0.94339623 | G31: ⬆️ | M31: 1 | N31: 0 | O31: 5 | P31: 0 | S31: campbellayers | T31: 2 | Z31: 2
A32: cloudwarriors-ai/github_issues_tracker | B32: GitHub Issues Tracker | C32: 2 | D32: 1 | E32: 3 | F32: 0.33333333 | G32: ↔️ | M32: 0 | N32: 0 | O32: 2 | P32: 0 | S32: rebecca-cichy | T32: 6 | V32: 1 | W32: 1 | X32: 2 | Y32: 2
A33: cloudwarriors-ai/automation-station | B33: Automation Station | C33: 2 | D33: 18 | E33: 20 | F33: 0.9 | G33: ↔️ | M33: 0 | N33: 0 | O33: 2 | P33: 0 | S33: DsuarezCW | T33: 2 | AA33: 2
A34: cloudwarriors-ai/codename_wad | B34: Zoom Workbook | C34: 12 | D34: 58 | E34: 70 | F34: 0.82857143 | G34: ↔️ | M34: 5 | N34: 0 | O34: 7 | P34: 0
A35: cloudwarriors-ai/github_review_build_test | B35: GitHub Review Build | C35: 16 | D35: 0 | E35: 16 | F35: 0 | G35: ↔️ | M35: 0 | N35: 0 | O35: 3 | P35: 13
A36: cloudwarriors-ai/chadwick | B36: Chadwick | C36: 1 | D36: 0 | E36: 1 | F36: 0 | G36: ↔️ | M36: 0 | N36: 1 | O36: 0 | P36: 0 | S36: TOTALS | T36: 60 | U36: 17 | V36: 4 | W36: 3 | X36: 3 | Y36: 19 | Z36: 2 | AA36: 8 | AB36: 2 | AC36: 2 | AD36: 0 | AE36: 0 | AF36: 0 | AG36: 0
A37: cloudwarriors-ai/support | B37: Support | C37: 1 | D37: 0 | E37: 1 | F37: 0 | G37: ↔️ | M37: 0 | N37: 0 | O37: 0 | P37: 1
A40: Date: 3Dec25 @ 6 AM EST | S40: Date: 3Dec25 @ 6 AM EST
A41: Repository | B41: App Name | C41: Open | D41: Closed | E41: Total | F41: % Complete | G41: Change | M41: P1: Task | N41: P2:Bug | O41: P3: Features | P41: Not Specified | S41: Name | T41: Task Count | U41: Tes-BE | V41: Tes-FE | X41: Rap | Y41: RapFE | Z41: PSO | AA41: ZWar | AB41: GIT | AC41: AS | AD41: ZWor | AE41: Git RB | AF41: Chad | AG41: Supp | AH41: TesPl | AI41: Notes
A42: cloudwarriors-ai/Tesseract | B42: Tesseract - Backend | C42: 14 | D42: 66 | E42: 80 | F42: 0.825 | G42: ⬆️ | M42: 13 | N42: 1 | O42: 0 | P42: 0 | S42: Voipin | T42: 0
A43: cloudwarriors-ai/tesseract-frontend | B43: Tesseract - Frontend | C43: 4 | D43: 58 | E43: 62 | F43: 0.93548387 | G43: ↔️ | M43: 1 | N43: 2 | O43: 1 | P43: 0 | S43: Chaddacus | T43: 13 | X43: 1 | Y43: 10 | AC43: 2
A44: cloudwarriors-ai/rapture | B44: MACD - Rapture | C44: 2 | D44: 28 | E44: 30 | F44: 0.93333333 | G44: ↔️ | M44: 0 | N44: 1 | O44: 1 | P44: 0 | S44: trentcharlton | T44: 12 | U44: 4 | V44: 1 | Y44: 7
A45: cloudwarriors-ai/rapture-frontend | B45: MACD - PSCX Frontend | C45: 19 | D45: 86 | E45: 105 | F45: 0.81904762 | G45: ↔️ | M45: 5 | N45: 3 | O45: 11 | P45: 0 | S45: Jeffrey-Searcy | T45: 6 | U45: 6
A46: cloudwarriors-ai/PSO-Quoting-Tool | B46: PSO Tool | C46: 2 | D46: 16 | E46: 18 | F46: 0.88888889 | G46: ↔️ | M46: 2 | N46: 0 | O46: 0 | P46: 0 | S46: jvitato1 | T46: 3 | V46: 1 | AB46: 2
A47: cloudwarriors-ai/zoom_presales_django | B47: Zoom Warriors | C47: 11 | D47: 94 | E47: 105 | F47: 0.8952381 | G47: ⬆️ | M47: 3 | N47: 0 | O47: 8 | P47: 0 | S47: Matt-Keuning | T47: 19 | U47: 7 | V47: 1 | AA47: 11
...

Sheet All Issues
A1: Repository | B1: System | C1: Issue Number | D1: Title | E1: State | F1: Created At | G1: Created At | H1: Created By | I1: Last Updated At | J1: Last Updated At | K1: Closed At | L1: Closed At | M1: Type | N1: Labels | O1: Assignees | P1: Comments Count | Q1: URL | R1: Priority | S1: Skill | T1: Status
A2: cloudwarriors-ai/cw-automation-station | B2: CW Automation Station | C2: 26 | D2: Feature Request - new V1 Common Area user setting modifications | E2: closed | F2: 2024-04-19T19:37:01Z | G2: =IF(I2="", "", TEXT(DATEVALUE(LEFT(F2, 10)), "dd-mmm-yyyy")) -> 19-Apr-2024 | H2: jondejonghcw | I2: 2025-06-12T15:34:16Z | J2: =IF(I2="", "", TEXT(DATEVALUE(LEFT(I2, 10)), "dd-mmm-yyyy")) -> 12-Jun-2025 | K2: 2025-06-12T15:34:16Z | L2: =IF(K2="", "", TEXT(DATEVALUE(LEFT(K2, 10)), "dd-mmm-yyyy")) -> 12-Jun-2025 | M2: Not Specified | N2: None | P2: 1 | Q2: https://github.com/cloudwarriors-ai/cw-automation-station/issues/26 | R2: =IFERROR(__xludf.DUMMYFUNCTION("IF(REGEXMATCH(N2, ""PRIORITY: Low""), ""Low"", IF(REGEXMATCH(N2, ""PRIORITY: Medium""), ""Medium"", IF(REGEXMATCH(N2, ""PRIORITY: High""), ""High"", """"))) "),"") | S2: =IFERROR(__xludf.DUMMYFUNCTION("IF(REGEXMATCH(N2, ""SKILL: Low""), ""Low"", IF(REGEXMATCH(N2, ""SKILL: Medium""), ""Medium"", IF(REGEXMATCH(N2, ""SKILL: High""), ""High"", """")))"),"") | T2: =IFERROR(__xludf.DUMMYFUNCTION("IF(REGEXMATCH(N2, ""STATUS: Dev Complete - Awaiting QA""), ""Dev Complete - Awaiting QA"", IF(REGEXMATCH(N2, ""STATUS: Follow-Up Required""), ""Follow-Up Required"", IF(REGEXMATCH(N2, ""STATUS: In Progress""), ""In Progress"", IF(REGEXMATCH(N2, ""STATUS: "&"In QA""), ""In QA"", IF(REGEXMATCH(N2, ""STATUS: Needs Customer Feedback""), ""Needs Customer Feedback"", IF(REGEXMATCH(N2, ""STATUS: QA Passed - Awaiting Release""), ""QA Passed - Awaiting Release"", IF(REGEXMATCH(N2, ""STATUS: Release to Prod""), ""Rele"&"ase to Prod"", """")))))))"),"")
A3: cloudwarriors-ai/cw-automation-station | B3: CW Automation Station | C3: 25 | D3: Feature Request - Enhance v1 Call Queue Overflow to include other destinations | E3: closed | F3: 2024-04-19T19:34:00Z | G3: =IF(I3="", "", TEXT(DATEVALUE(LEFT(F3, 10)), "dd-mmm-yyyy")) -> 19-Apr-2024 | H3: jondejonghcw | I3: 2025-06-12T15:34:24Z | J3: =IF(I3="", "", TEXT(DATEVALUE(LEFT(I3, 10)), "dd-mmm-yyyy")) -> 12-Jun-2025 | K3: 2025-06-12T15:34:24Z | L3: =IF(K3="", "", TEXT(DATEVALUE(LEFT(K3, 10)), "dd-mmm-yyyy")) -> 12-Jun-2025 | M3: Not Specified | N3: None | P3: 1 | Q3: https://github.com/cloudwarriors-ai/cw-automation-station/issues/25 | R3: =IFERROR(__xludf.DUMMYFUNCTION("IF(REGEXMATCH(N3, ""PRIORITY: Low""), ""Low"", IF(REGEXMATCH(N3, ""PRIORITY: Medium""), ""Medium"", IF(REGEXMATCH(N3, ""PRIORITY: High""), ""High"", """"))) "),"") | S3: =IFERROR(__xludf.DUMMYFUNCTION("IF(REGEXMATCH(N3, ""SKILL: Low""), ""Low"", IF(REGEXMATCH(N3, ""SKILL: Medium""), ""Medium"", IF(REGEXMATCH(N3, ""SKILL: High""), ""High"", """")))"),"") | T3: =IFERROR(__xludf.DUMMYFUNCTION("IF(REGEXMATCH(N3, ""STATUS: Dev Complete - Awaiting QA""), ""Dev Complete - Awaiting QA"", IF(REGEXMATCH(N3, ""STATUS: Follow-Up Required""), ""Follow-Up Required"", IF(REGEXMATCH(N3, ""STATUS: In Progress""), ""In Progress"", IF(REGEXMATCH(N3, ""STATUS: "&"In QA""), ""In QA"", IF(REGEXMATCH(N3, ""STATUS: Needs Customer Feedback""), ""Needs Customer Feedback"", IF(REGEXMATCH(N3, ""STATUS: QA Passed - Awaiting Release""), ""QA Passed - Awaiting Release"", IF(REGEXMATCH(N3, ""STATUS: Release to Prod""), ""Rele"&"ase to Prod"", """")))))))"),"")
A4: cloudwarriors-ai/cw-automation-station | B4: CW Automation Station | C4: 24 | D4: Feature Request - Add Description Field in CSV files | E4: closed | F4: 2024-04-19T19:31:25Z | G4: =IF(I4="", "", TEXT(DATEVALUE(LEFT(F4, 10)), "dd-mmm-yyyy")) -> 19-Apr-2024 | H4: jondejonghcw | I4: 2025-06-12T15:34:30Z | J4: =IF(I4="", "", TEXT(DATEVALUE(LEFT(I4, 10)), "dd-mmm-yyyy")) -> 12-Jun-2025 | K4: 2025-06-12T15:34:30Z | L4: =IF(K4="", "", TEXT(DATEVALUE(LEFT(K4, 10)), "dd-mmm-yyyy")) -> 12-Jun-2025 | M4: Not Specified | N4: None | P4: 1 | Q4: https://github.com/cloudwarriors-ai/cw-automation-station/issues/24 | R4: =IFERROR(__xludf.DUMMYFUNCTION("IF(REGEXMATCH(N4, ""PRIORITY: Low""), ""Low"", IF(REGEXMATCH(N4, ""PRIORITY: Medium""), ""Medium"", IF(REGEXMATCH(N4, ""PRIORITY: High""), ""High"", """"))) "),"") | S4: =IFERROR(__xludf.DUMMYFUNCTION("IF(REGEXMATCH(N4, ""SKILL: Low""), ""Low"", IF(REGEXMATCH(N4, ""SKILL: Medium""), ""Medium"", IF(REGEXMATCH(N4, ""SKILL: High""), ""High"", """")))"),"") | T4: =IFERROR(__xludf.DUMMYFUNCTION("IF(REGEXMATCH(N4, ""STATUS: Dev Complete - Awaiting QA""), ""Dev Complete - Awaiting QA"", IF(REGEXMATCH(N4, ""STATUS: Follow-Up Required""), ""Follow-Up Required"", IF(REGEXMATCH(N4, ""STATUS: In Progress""), ""In Progress"", IF(REGEXMATCH(N4, ""STATUS: "&"In QA""), ""In QA"", IF(REGEXMATCH(N4, ""STATUS: Needs Customer Feedback""), ""Needs Customer Feedback"", IF(REGEXMATCH(N4, ""STATUS: QA Passed - Awaiting Release""), ""QA Passed - Awaiting Release"", IF(REGEXMATCH(N4, ""STATUS: Release to Prod""), ""Rele"&"ase to Prod"", """")))))))"),"")
A5: cloudwarriors-ai/cw-automation-station | B5: CW Automation Station | C5: 15 | D5: Feature Request: Test Zoom generated SDK for Contact Center | E5: closed | F5: 2024-02-12T17:13:38Z | G5: =IF(I5="", "", TEXT(DATEVALUE(LEFT(F5, 10)), "dd-mmm-yyyy")) -> 12-Feb-2024 | H5: CkirkCW | I5: 2025-06-12T15:35:05Z | J5: =IF(I5="", "", TEXT(DATEVALUE(LEFT(I5, 10)), "dd-mmm-yyyy")) -> 12-Jun-2025 | K5: 2025-06-12T15:35:05Z | L5: =IF(K5="", "", TEXT(DATEVALUE(LEFT(K5, 10)), "dd-mmm-yyyy")) -> 12-Jun-2025 | M5: Not Specified | N5: None | P5: 1 | Q5: https://github.com/cloudwarriors-ai/cw-automation-station/issues/15 | R5: =IFERROR(__xludf.DUMMYFUNCTION("IF(REGEXMATCH(N5, ""PRIORITY: Low""), ""Low"", IF(REGEXMATCH(N5, ""PRIORITY: Medium""), ""Medium"", IF(REGEXMATCH(N5, ""PRIORITY: High""), ""High"", """"))) "),"") | S5: =IFERROR(__xludf.DUMMYFUNCTION("IF(REGEXMATCH(N5, ""SKILL: Low""), ""Low"", IF(REGEXMATCH(N5, ""SKILL: Medium""), ""Medium"", IF(REGEXMATCH(N5, ""SKILL: High""), ""High"", """")))"),"") | T5: =IFERROR(__xludf.DUMMYFUNCTION("IF(REGEXMATCH(N5, ""STATUS: Dev Complete - Awaiting QA""), ""Dev Complete - Awaiting QA"", IF(REGEXMATCH(N5, ""STATUS: Follow-Up Required""), ""Follow-Up Required"", IF(REGEXMATCH(N5, ""STATUS: In Progress""), ""In Progress"", IF(REGEXMATCH(N5, ""STATUS: "&"In QA""), ""In QA"", IF(REGEXMATCH(N5, ""STATUS: Needs Customer Feedback""), ""Needs Customer Feedback"", IF(REGEXMATCH(N5, ""STATUS: QA Passed - Awaiting Release""), ""QA Passed - Awaiting Release"", IF(REGEXMATCH(N5, ""STATUS: Release to Prod""), ""Rele"&"ase to Prod"", """")))))))"),"")
A6: cloudwarriors-ai/cw-automation-station | B6: CW Automation Station | C6: 11 | D6: Login Redirect Issue | E6: closed | F6: 2024-01-31T14:54:44Z | G6: =IF(I6="", "", TEXT(DATEVALUE(LEFT(F6, 10)), "dd-mmm-yyyy")) -> 31-Jan-2024 | H6: CkirkCW | I6: 2024-02-12T21:29:16Z | J6: =IF(I6="", "", TEXT(DATEVALUE(LEFT(I6, 10)), "dd-mmm-yyyy")) -> 12-Feb-2024 | K6: 2024-02-12T21:29:16Z | L6: =IF(K6="", "", TEXT(DATEVALUE(LEFT(K6, 10)), "dd-mmm-yyyy")) -> 12-Feb-2024 | M6: Not Specified | N6: None | P6: 1 | Q6: https://github.com/cloudwarriors-ai/cw-automation-station/issues/11 | R6: =IFERROR(__xludf.DUMMYFUNCTION("IF(REGEXMATCH(N6, ""PRIORITY: Low""), ""Low"", IF(REGEXMATCH(N6, ""PRIORITY: Medium""), ""Medium"", IF(REGEXMATCH(N6, ""PRIORITY: High""), ""High"", """"))) "),"") | S6: =IFERROR(__xludf.DUMMYFUNCTION("IF(REGEXMATCH(N6, ""SKILL: Low""), ""Low"", IF(REGEXMATCH(N6, ""SKILL: Medium""), ""Medium"", IF(REGEXMATCH(N6, ""SKILL: High""), ""High"", """")))"),"") | T6: =IFERROR(__xludf.DUMMYFUNCTION("IF(REGEXMATCH(N6, ""STATUS: Dev Complete - Awaiting QA""), ""Dev Complete - Awaiting QA"", IF(REGEXMATCH(N6, ""STATUS: Follow-Up Required""), ""Follow-Up Required"", IF(REGEXMATCH(N6, ""STATUS: In Progress""), ""In Progress"", IF(REGEXMATCH(N6, ""STATUS: "&"In QA""), ""In QA"", IF(REGEXMATCH(N6, ""STATUS: Needs Customer Feedback""), ""Needs Customer Feedback"", IF(REGEXMATCH(N6, ""STATUS: QA Passed - Awaiting Release""), ""QA Passed - Awaiting Release"", IF(REGEXMATCH(N6, ""STATUS: Release to Prod""), ""Rele"&"ase to Prod"", """")))))))"),"")
A7: cloudwarriors-ai/cw-automation-station | B7: CW Automation Station | C7: 8 | D7: Remote DB not adding new users to database at insert_into_database | E7: closed | F7: 2024-01-30T17:30:00Z | G7: =IF(I7="", "", TEXT(DATEVALUE(LEFT(F7, 10)), "dd-mmm-yyyy")) -> 30-Jan-2024 | H7: trentcharlton | I7: 2025-06-12T15:34:58Z | J7: =IF(I7="", "", TEXT(DATEVALUE(LEFT(I7, 10)), "dd-mmm-yyyy")) -> 12-Jun-2025 | K7: 2025-06-12T15:34:58Z | L7: =IF(K7="", "", TEXT(DATEVALUE(LEFT(K7, 10)), "dd-mmm-yyyy")) -> 12-Jun-2025 | M7: Not Specified | N7: None | P7: 1 | Q7: https://github.com/cloudwarriors-ai/cw-automation-station/issues/8 | R7: =IFERROR(__xludf.DUMMYFUNCTION("IF(REGEXMATCH(N7, ""PRIORITY: Low""), ""Low"", IF(REGEXMATCH(N7, ""PRIORITY: Medium""), ""Medium"", IF(REGEXMATCH(N7, ""PRIORITY: High""), ""High"", """"))) "),"") | S7: =IFERROR(__xludf.DUMMYFUNCTION("IF(REGEXMATCH(N7, ""SKILL: Low""), ""Low"", IF(REGEXMATCH(N7, ""SKILL: Medium""), ""Medium"", IF(REGEXMATCH(N7, ""SKILL: High""), ""High"", """")))"),"") | T7: =IFERROR(__xludf.DUMMYFUNCTION("IF(REGEXMATCH(N7, ""STATUS: Dev Complete - Awaiting QA""), ""Dev Complete - Awaiting QA"", IF(REGEXMATCH(N7, ""STATUS: Follow-Up Required""), ""Follow-Up Required"", IF(REGEXMATCH(N7, ""STATUS: In Progress""), ""In Progress"", IF(REGEXMATCH(N7, ""STATUS: "&"In QA""), ""In QA"", IF(REGEXMATCH(N7, ""STATUS: Needs Customer Feedback""), ""Needs Customer Feedback"", IF(REGEXMATCH(N7, ""STATUS: QA Passed - Awaiting Release""), ""QA Passed - Awaiting Release"", IF(REGEXMATCH(N7, ""STATUS: Release to Prod""), ""Rele"&"ase to Prod"", """")))))))"),"")
A8: cloudwarriors-ai/cw-automation-station | B8: CW Automation Station | C8: 7 | D8: Process_user_data possible infinite loop | E8: closed | F8: 2024-01-30T17:27:06Z | G8: =IF(I8="", "", TEXT(DATEVALUE(LEFT(F8, 10)), "dd-mmm-yyyy")) -> 30-Jan-2024 | H8: trentcharlton | I8: 2024-05-07T20:53:49Z | J8: =IF(I8="", "", TEXT(DATEVALUE(LEFT(I8, 10)), "dd-mmm-yyyy")) -> 07-May-2024 | K8: 2024-01-30T20:57:01Z | L8: =IF(K8="", "", TEXT(DATEVALUE(LEFT(K8, 10)), "dd-mmm-yyyy")) -> 30-Jan-2024 | M8: Not Specified | N8: None | P8: 0 | Q8: https://github.com/cloudwarriors-ai/cw-automation-station/issues/7 | R8: =IFERROR(__xludf.DUMMYFUNCTION("IF(REGEXMATCH(N8, ""PRIORITY: Low""), ""Low"", IF(REGEXMATCH(N8, ""PRIORITY: Medium""), ""Medium"", IF(REGEXMATCH(N8, ""PRIORITY: High""), ""High"", """"))) "),"") | S8: =IFERROR(__xludf.DUMMYFUNCTION("IF(REGEXMATCH(N8, ""SKILL: Low""), ""Low"", IF(REGEXMATCH(N8, ""SKILL: Medium""), ""Medium"", IF(REGEXMATCH(N8, ""SKILL: High""), ""High"", """")))"),"") | T8: =IFERROR(__xludf.DUMMYFUNCTION("IF(REGEXMATCH(N8, ""STATUS: Dev Complete - Awaiting QA""), ""Dev Complete - Awaiting QA"", IF(REGEXMATCH(N8, ""STATUS: Follow-Up Required""), ""Follow-Up Required"", IF(REGEXMATCH(N8, ""STATUS: In Progress""), ""In Progress"", IF(REGEXMATCH(N8, ""STATUS: "&"In QA""), ""In QA"", IF(REGEXMATCH(N8, ""STATUS: Needs Customer Feedback""), ""Needs Customer Feedback"", IF(REGEXMATCH(N8, ""STATUS: QA Passed - Awaiting Release""), ""QA Passed - Awaiting Release"", IF(REGEXMATCH(N8, ""STATUS: Release to Prod""), ""Rele"&"ase to Prod"", """")))))))"),"")
A9: cloudwarriors-ai/cw-automation-station | B9: CW Automation Station | C9: 5 | D9: phone call queue manager needs to get the manger ID to insert | E9: closed | F9: 2024-01-23T20:58:08Z | G9: =IF(I9="", "", TEXT(DATEVALUE(LEFT(F9, 10)), "dd-mmm-yyyy")) -> 23-Jan-2024 | H9: voipin | I9: 2025-06-12T15:34:52Z | J9: =IF(I9="", "", TEXT(DATEVALUE(LEFT(I9, 10)), "dd-mmm-yyyy")) -> 12-Jun-2025 | K9: 2025-06-12T15:34:52Z | L9: =IF(K9="", "", TEXT(DATEVALUE(LEFT(K9, 10)), "dd-mmm-yyyy")) -> 12-Jun-2025 | M9: Not Specified | N9: None | P9: 1 | Q9: https://github.com/cloudwarriors-ai/cw-automation-station/issues/5 | R9: =IFERROR(__xludf.DUMMYFUNCTION("IF(REGEXMATCH(N9, ""PRIORITY: Low""), ""Low"", IF(REGEXMATCH(N9, ""PRIORITY: Medium""), ""Medium"", IF(REGEXMATCH(N9, ""PRIORITY: High""), ""High"", """"))) "),"") | S9: =IFERROR(__xludf.DUMMYFUNCTION("IF(REGEXMATCH(N9, ""SKILL: Low""), ""Low"", IF(REGEXMATCH(N9, ""SKILL: Medium""), ""Medium"", IF(REGEXMATCH(N9, ""SKILL: High""), ""High"", """")))"),"") | T9: =IFERROR(__xludf.DUMMYFUNCTION("IF(REGEXMATCH(N9, ""STATUS: Dev Complete - Awaiting QA""), ""Dev Complete - Awaiting QA"", IF(REGEXMATCH(N9, ""STATUS: Follow-Up Required""), ""Follow-Up Required"", IF(REGEXMATCH(N9, ""STATUS: In Progress""), ""In Progress"", IF(REGEXMATCH(N9, ""STATUS: "&"In QA""), ""In QA"", IF(REGEXMATCH(N9, ""STATUS: Needs Customer Feedback""), ""Needs Customer Feedback"", IF(REGEXMATCH(N9, ""STATUS: QA Passed - Awaiting Release""), ""QA Passed - Awaiting Release"", IF(REGEXMATCH(N9, ""STATUS: Release to Prod""), ""Rele"&"ase to Prod"", """")))))))"),"")
A10: cloudwarriors-ai/cw-automation-station | B10: CW Automation Station | C10: 4 | D10: call_queue member doesn't work , missing data | E10: closed | F10: 2024-01-23T20:57:19Z | G10: =IF(I10="", "", TEXT(DATEVALUE(LEFT(F10, 10)), "dd-mmm-yyyy")) -> 23-Jan-2024 | H10: voipin | I10: 2025-06-12T15:34:46Z | J10: =IF(I10="", "", TEXT(DATEVALUE(LEFT(I10, 10)), "dd-mmm-yyyy")) -> 12-Jun-2025 | K10: 2025-06-12T15:34:46Z | L10: =IF(K10="", "", TEXT(DATEVALUE(LEFT(K10, 10)), "dd-mmm-yyyy")) -> 12-Jun-2025 | M10: Not Specified | N10: None | P10: 1 | Q10: https://github.com/cloudwarriors-ai/cw-automation-station/issues/4 | R10: =IFERROR(__xludf.DUMMYFUNCTION("IF(REGEXMATCH(N10, ""PRIORITY: Low""), ""Low"", IF(REGEXMATCH(N10, ""PRIORITY: Medium""), ""Medium"", IF(REGEXMATCH(N10, ""PRIORITY: High""), ""High"", """"))) "),"") | S10: =IFERROR(__xludf.DUMMYFUNCTION("IF(REGEXMATCH(N10, ""SKILL: Low""), ""Low"", IF(REGEXMATCH(N10, ""SKILL: Medium""), ""Medium"", IF(REGEXMATCH(N10, ""SKILL: High""), ""High"", """")))"),"") | T10: =IFERROR(__xludf.DUMMYFUNCTION("IF(REGEXMATCH(N10, ""STATUS: Dev Complete - Awaiting QA""), ""Dev Complete - Awaiting QA"", IF(REGEXMATCH(N10, ""STATUS: Follow-Up Required""), ""Follow-Up Required"", IF(REGEXMATCH(N10, ""STATUS: In Progress""), ""In Progress"", IF(REGEXMATCH(N10, ""STAT"&"US: In QA""), ""In QA"", IF(REGEXMATCH(N10, ""STATUS: Needs Customer Feedback""), ""Needs Customer Feedback"", IF(REGEXMATCH(N10, ""STATUS: QA Passed - Awaiting Release""), ""QA Passed - Awaiting Release"", IF(REGEXMATCH(N10, ""STATUS: Release to Prod""),"&" ""Release to Prod"", """")))))))"),"")
A11: cloudwarriors-ai/cw-automation-station | B11: CW Automation Station | C11: 3 | D11: Validation button/alerts | E11: closed | F11: 2024-01-22T20:00:06Z | G11: =IF(I11="", "", TEXT(DATEVALUE(LEFT(F11, 10)), "dd-mmm-yyyy")) -> 22-Jan-2024 | H11: CkirkCW | I11: 2025-06-12T15:34:39Z | J11: =IF(I11="", "", TEXT(DATEVALUE(LEFT(I11, 10)), "dd-mmm-yyyy")) -> 12-Jun-2025 | K11: 2025-06-12T15:34:39Z | L11: =IF(K11="", "", TEXT(DATEVALUE(LEFT(K11, 10)), "dd-mmm-yyyy")) -> 12-Jun-2025 | M11: Not Specified | N11: None | P11: 3 | Q11: https://github.com/cloudwarriors-ai/cw-automation-station/issues/3 | R11: =IFERROR(__xludf.DUMMYFUNCTION("IF(REGEXMATCH(N11, ""PRIORITY: Low""), ""Low"", IF(REGEXMATCH(N11, ""PRIORITY: Medium""), ""Medium"", IF(REGEXMATCH(N11, ""PRIORITY: High""), ""High"", """"))) "),"") | S11: =IFERROR(__xludf.DUMMYFUNCTION("IF(REGEXMATCH(N11, ""SKILL: Low""), ""Low"", IF(REGEXMATCH(N11, ""SKILL: Medium""), ""Medium"", IF(REGEXMATCH(N11, ""SKILL: High""), ""High"", """")))"),"") | T11: =IFERROR(__xludf.DUMMYFUNCTION("IF(REGEXMATCH(N11, ""STATUS: Dev Complete - Awaiting QA""), ""Dev Complete - Awaiting QA"", IF(REGEXMATCH(N11, ""STATUS: Follow-Up Required""), ""Follow-Up Required"", IF(REGEXMATCH(N11, ""STATUS: In Progress""), ""In Progress"", IF(REGEXMATCH(N11, ""STAT"&"US: In QA""), ""In QA"", IF(REGEXMATCH(N11, ""STATUS: Needs Customer Feedback""), ""Needs Customer Feedback"", IF(REGEXMATCH(N11, ""STATUS: QA Passed - Awaiting Release""), ""QA Passed - Awaiting Release"", IF(REGEXMATCH(N11, ""STATUS: Release to Prod""),"&" ""Release to Prod"", """")))))))"),"")
A12: cloudwarriors-ai/cw-automation-station | B12: CW Automation Station | C12: 2 | D12: User email redirection - update zoom OAUTH not redirecting to index | E12: closed | F12: 2024-01-19T22:15:23Z | G12: =IF(I12="", "", TEXT(DATEVALUE(LEFT(F12, 10)), "dd-mmm-yyyy")) -> 19-Jan-2024 | H12: CkirkCW | I12: 2024-01-19T22:22:10Z | J12: =IF(I12="", "", TEXT(DATEVALUE(LEFT(I12, 10)), "dd-mmm-yyyy")) -> 19-Jan-2024 | K12: 2024-01-19T22:22:10Z | L12: =IF(K12="", "", TEXT(DATEVALUE(LEFT(K12, 10)), "dd-mmm-yyyy")) -> 19-Jan-2024 | M12: Not Specified | N12: None | P12: 0 | Q12: https://github.com/cloudwarriors-ai/cw-automation-station/issues/2 | R12: =IFERROR(__xludf.DUMMYFUNCTION("IF(REGEXMATCH(N12, ""PRIORITY: Low""), ""Low"", IF(REGEXMATCH(N12, ""PRIORITY: Medium""), ""Medium"", IF(REGEXMATCH(N12, ""PRIORITY: High""), ""High"", """"))) "),"") | S12: =IFERROR(__xludf.DUMMYFUNCTION("IF(REGEXMATCH(N12, ""SKILL: Low""), ""Low"", IF(REGEXMATCH(N12, ""SKILL: Medium""), ""Medium"", IF(REGEXMATCH(N12, ""SKILL: High""), ""High"", """")))"),"") | T12: =IFERROR(__xludf.DUMMYFUNCTION("IF(REGEXMATCH(N12, ""STATUS: Dev Complete - Awaiting QA""), ""Dev Complete - Awaiting QA"", IF(REGEXMATCH(N12, ""STATUS: Follow-Up Required""), ""Follow-Up Required"", IF(REGEXMATCH(N12, ""STATUS: In Progress""), ""In Progress"", IF(REGEXMATCH(N12, ""STAT"&"US: In QA""), ""In QA"", IF(REGEXMATCH(N12, ""STATUS: Needs Customer Feedback""), ""Needs Customer Feedback"", IF(REGEXMATCH(N12, ""STATUS: QA Passed - Awaiting Release""), ""QA Passed - Awaiting Release"", IF(REGEXMATCH(N12, ""STATUS: Release to Prod""),"&" ""Release to Prod"", """")))))))"),"")
A13: cloudwarriors-ai/cw-automation-station | B13: CW Automation Station | C13: 1 | D13: Check for file before upload button is functional | E13: closed | F13: 2024-01-17T18:45:10Z | G13: =IF(I13="", "", TEXT(DATEVALUE(LEFT(F13, 10)), "dd-mmm-yyyy")) -> 17-Jan-2024 | H13: voipin | I13: 2024-01-30T20:57:16Z | J13: =IF(I13="", "", TEXT(DATEVALUE(LEFT(I13, 10)), "dd-mmm-yyyy")) -> 30-Jan-2024 | K13: 2024-01-30T20:57:15Z | L13: =IF(K13="", "", TEXT(DATEVALUE(LEFT(K13, 10)), "dd-mmm-yyyy")) -> 30-Jan-2024 | M13: Not Specified | N13: None | P13: 0 | Q13: https://github.com/cloudwarriors-ai/cw-automation-station/issues/1 | R13: =IFERROR(__xludf.DUMMYFUNCTION("IF(REGEXMATCH(N13, ""PRIORITY: Low""), ""Low"", IF(REGEXMATCH(N13, ""PRIORITY: Medium""), ""Medium"", IF(REGEXMATCH(N13, ""PRIORITY: High""), ""High"", """"))) "),"") | S13: =IFERROR(__xludf.DUMMYFUNCTION("IF(REGEXMATCH(N13, ""SKILL: Low""), ""Low"", IF(REGEXMATCH(N13, ""SKILL: Medium""), ""Medium"", IF(REGEXMATCH(N13, ""SKILL: High""), ""High"", """")))"),"") | T13: =IFERROR(__xludf.DUMMYFUNCTION("IF(REGEXMATCH(N13, ""STATUS: Dev Complete - Awaiting QA""), ""Dev Complete - Awaiting QA"", IF(REGEXMATCH(N13, ""STATUS: Follow-Up Required""), ""Follow-Up Required"", IF(REGEXMATCH(N13, ""STATUS: In Progress""), ""In Progress"", IF(REGEXMATCH(N13, ""STAT"&"US: In QA""), ""In QA"", IF(REGEXMATCH(N13, ""STATUS: Needs Customer Feedback""), ""Needs Customer Feedback"", IF(REGEXMATCH(N13, ""STATUS: QA Passed - Awaiting Release""), ""QA Passed - Awaiting Release"", IF(REGEXMATCH(N13, ""STATUS: Release to Prod""),"&" ""Release to Prod"", """")))))))"),"")
A14: cloudwarriors-ai/automation-station | B14: Automation Station | C14: 58 | D14: Zoom Phone - Need to have the option to add extra e911 zones | E14: closed | F14: 2025-04-08T18:50:21Z | G14: =IF(I14="", "", TEXT(DATEVALUE(LEFT(F14, 10)), "dd-mmm-yyyy")) -> 08-Apr-2025 | H14: rebecca-cichy | I14: 2025-07-11T21:07:52Z | J14: =IF(I14="", "", TEXT(DATEVALUE(LEFT(I14, 10)), "dd-mmm-yyyy")) -> 11-Jul-2025 | K14: 2025-04-08T18:55:46Z | L14: =IF(K14="", "", TEXT(DATEVALUE(LEFT(K14, 10)), "dd-mmm-yyyy")) -> 08-Apr-2025 | M14: Not Specified | N14: None | P14: 0 | Q14: https://github.com/cloudwarriors-ai/automation-station/issues/58 | R14: =IFERROR(__xludf.DUMMYFUNCTION("IF(REGEXMATCH(N14, ""PRIORITY: Low""), ""Low"", IF(REGEXMATCH(N14, ""PRIORITY: Medium""), ""Medium"", IF(REGEXMATCH(N14, ""PRIORITY: High""), ""High"", """"))) "),"") | S14: =IFERROR(__xludf.DUMMYFUNCTION("IF(REGEXMATCH(N14, ""SKILL: Low""), ""Low"", IF(REGEXMATCH(N14, ""SKILL: Medium""), ""Medium"", IF(REGEXMATCH(N14, ""SKILL: High""), ""High"", """")))"),"") | T14: =IFERROR(__xludf.DUMMYFUNCTION("IF(REGEXMATCH(N14, ""STATUS: Dev Complete - Awaiting QA""), ""Dev Complete - Awaiting QA"", IF(REGEXMATCH(N14, ""STATUS: Follow-Up Required""), ""Follow-Up Required"", IF(REGEXMATCH(N14, ""STATUS: In Progress""), ""In Progress"", IF(REGEXMATCH(N14, ""STAT"&"US: In QA""), ""In QA"", IF(REGEXMATCH(N14, ""STATUS: Needs Customer Feedback""), ""Needs Customer Feedback"", IF(REGEXMATCH(N14, ""STATUS: QA Passed - Awaiting Release""), ""QA Passed - Awaiting Release"", IF(REGEXMATCH(N14, ""STATUS: Release to Prod""),"&" ""Release to Prod"", """")))))))"),"")
A15: cloudwarriors-ai/automation-station | B15: Automation Station | C15: 55 | D15: SLA not being correctly pulled when job is created | E15: closed | F15: 2025-02-26T14:00:38Z | G15: =IF(I15="", "", TEXT(DATEVALUE(LEFT(F15, 10)), "dd-mmm-yyyy")) -> 26-Feb-2025 | H15: Chaddacus | I15: 2025-07-11T21:07:54Z | J15: =IF(I15="", "", TEXT(DATEVALUE(LEFT(I15, 10)), "dd-mmm-yyyy")) -> 11-Jul-2025 | K15: 2025-06-12T15:13:33Z | L15: =IF(K15="", "", TEXT(DATEVALUE(LEFT(K15, 10)), "dd-mmm-yyyy")) -> 12-Jun-2025 | M15: Not Specified | N15: None | P15: 1 | Q15: https://github.com/cloudwarriors-ai/automation-station/issues/55 | R15: =IFERROR(__xludf.DUMMYFUNCTION("IF(REGEXMATCH(N15, ""PRIORITY: Low""), ""Low"", IF(REGEXMATCH(N15, ""PRIORITY: Medium""), ""Medium"", IF(REGEXMATCH(N15, ""PRIORITY: High""), ""High"", """"))) "),"") | S15: =IFERROR(__xludf.DUMMYFUNCTION("IF(REGEXMATCH(N15, ""SKILL: Low""), ""Low"", IF(REGEXMATCH(N15, ""SKILL: Medium""), ""Medium"", IF(REGEXMATCH(N15, ""SKILL: High""), ""High"", """")))"),"") | T15: =IFERROR(__xludf.DUMMYFUNCTION("IF(REGEXMATCH(N15, ""STATUS: Dev Complete - Awaiting QA""), ""Dev Complete - Awaiting QA"", IF(REGEXMATCH(N15, ""STATUS: Follow-Up Required""), ""Follow-Up Required"", IF(REGEXMATCH(N15, ""STATUS: In Progress""), ""In Progress"", IF(REGEXMATCH(N15, ""STAT"&"US: In QA""), ""In QA"", IF(REGEXMATCH(N15, ""STATUS: Needs Customer Feedback""), ""Needs Customer Feedback"", IF(REGEXMATCH(N15, ""STATUS: QA Passed - Awaiting Release""), ""QA Passed - Awaiting Release"", IF(REGEXMATCH(N15, ""STATUS: Release to Prod""),"&" ""Release to Prod"", """")))))))"),"")
A16: cloudwarriors-ai/automation-station | B16: Automation Station | C16: 54 | D16: List jobs need to be exempt from SLA | E16: closed | F16: 2025-02-26T13:59:26Z | G16: =IF(I16="", "", TEXT(DATEVALUE(LEFT(F16, 10)), "dd-mmm-yyyy")) -> 26-Feb-2025 | H16: Chaddacus | I16: 2025-07-11T21:07:55Z | J16: =IF(I16="", "", TEXT(DATEVALUE(LEFT(I16, 10)), "dd-mmm-yyyy")) -> 11-Jul-2025 | K16: 2025-06-12T15:14:11Z | L16: =IF(K16="", "", TEXT(DATEVALUE(LEFT(K16, 10)), "dd-mmm-yyyy")) -> 12-Jun-2025 | M16: Not Specified | N16: None | P16: 1 | Q16: https://github.com/cloudwarriors-ai/automation-station/issues/54 | R16: =IFERROR(__xludf.DUMMYFUNCTION("IF(REGEXMATCH(N16, ""PRIORITY: Low""), ""Low"", IF(REGEXMATCH(N16, ""PRIORITY: Medium""), ""Medium"", IF(REGEXMATCH(N16, ""PRIORITY: High""), ""High"", """"))) "),"") | S16: =IFERROR(__xludf.DUMMYFUNCTION("IF(REGEXMATCH(N16, ""SKILL: Low""), ""Low"", IF(REGEXMATCH(N16, ""SKILL: Medium""), ""Medium"", IF(REGEXMATCH(N16, ""SKILL: High""), ""High"", """")))"),"") | T16: =IFERROR(__xludf.DUMMYFUNCTION("IF(REGEXMATCH(N16, ""STATUS: Dev Complete - Awaiting QA""), ""Dev Complete - Awaiting QA"", IF(REGEXMATCH(N16, ""STATUS: Follow-Up Required""), ""Follow-Up Required"", IF(REGEXMATCH(N16, ""STATUS: In Progress""), ""In Progress"", IF(REGEXMATCH(N16, ""STAT"&"US: In QA""), ""In QA"", IF(REGEXMATCH(N16, ""STATUS: Needs Customer Feedback""), ""Needs Customer Feedback"", IF(REGEXMATCH(N16, ""STATUS: QA Passed - Awaiting Release""), ""QA Passed - Awaiting Release"", IF(REGEXMATCH(N16, ""STATUS: Release to Prod""),"&" ""Release to Prod"", """")))))))"),"")
A17: cloudwarriors-ai/automation-station | B17: Automation Station | C17: 53 | D17: Jobs not properly moving between tables based on status | E17: closed | F17: 2025-02-26T13:58:07Z | G17: =IF(I17="", "", TEXT(DATEVALUE(LEFT(F17, 10)), "dd-mmm-yyyy")) -> 26-Feb-2025 | H17: Chaddacus | I17: 2025-07-11T21:07:55Z | J17: =IF(I17="", "", TEXT(DATEVALUE(LEFT(I17, 10)), "dd-mmm-yyyy")) -> 11-Jul-2025 | K17: 2025-06-12T15:19:19Z | L17: =IF(K17="", "", TEXT(DATEVALUE(LEFT(K17, 10)), "dd-mmm-yyyy")) -> 12-Jun-2025 | M17: Not Specified | N17: None | P17: 1 | Q17: https://github.com/cloudwarriors-ai/automation-station/issues/53 | R17: =IFERROR(__xludf.DUMMYFUNCTION("IF(REGEXMATCH(N17, ""PRIORITY: Low""), ""Low"", IF(REGEXMATCH(N17, ""PRIORITY: Medium""), ""Medium"", IF(REGEXMATCH(N17, ""PRIORITY: High""), ""High"", """"))) "),"") | S17: =IFERROR(__xludf.DUMMYFUNCTION("IF(REGEXMATCH(N17, ""SKILL: Low""), ""Low"", IF(REGEXMATCH(N17, ""SKILL: Medium""), ""Medium"", IF(REGEXMATCH(N17, ""SKILL: High""), ""High"", """")))"),"") | T17: =IFERROR(__xludf.DUMMYFUNCTION("IF(REGEXMATCH(N17, ""STATUS: Dev Complete - Awaiting QA""), ""Dev Complete - Awaiting QA"", IF(REGEXMATCH(N17, ""STATUS: Follow-Up Required""), ""Follow-Up Required"", IF(REGEXMATCH(N17, ""STATUS: In Progress""), ""In Progress"", IF(REGEXMATCH(N17, ""STAT"&"US: In QA""), ""In QA"", IF(REGEXMATCH(N17, ""STATUS: Needs Customer Feedback""), ""Needs Customer Feedback"", IF(REGEXMATCH(N17, ""STATUS: QA Passed - Awaiting Release""), ""QA Passed - Awaiting Release"", IF(REGEXMATCH(N17, ""STATUS: Release to Prod""),"&" ""Release to Prod"", """")))))))"),"")
A18: cloudwarriors-ai/automation-station | B18: Automation Station | C18: 52 | D18: Job Page - Rework/Touch Up | E18: open | F18: 2025-02-26T13:56:48Z | G18: =IF(I18="", "", TEXT(DATEVALUE(LEFT(F18, 10)), "dd-mmm-yyyy")) -> 26-Feb-2025 | H18: Chaddacus | I18: 2025-12-03T11:34:20Z | J18: =IF(I18="", "", TEXT(DATEVALUE(LEFT(I18, 10)), "dd-mmm-yyyy")) -> 03-Dec-2025 | L18: =IF(K18="", "", TEXT(DATEVALUE(LEFT(K18, 10)), "dd-mmm-yyyy")) | M18: Feature | N18: PRIORITY: Low, SKILL: Low, STATUS: In Progress | O18: Chaddacus | P18: 0 | Q18: https://github.com/cloudwarriors-ai/automation-station/issues/52 | R18: =IFERROR(__xludf.DUMMYFUNCTION("IF(REGEXMATCH(N18, ""PRIORITY: Low""), ""Low"", IF(REGEXMATCH(N18, ""PRIORITY: Medium""), ""Medium"", IF(REGEXMATCH(N18, ""PRIORITY: High""), ""High"", """"))) "),"Low") -> Low | S18: =IFERROR(__xludf.DUMMYFUNCTION("IF(REGEXMATCH(N18, ""SKILL: Low""), ""Low"", IF(REGEXMATCH(N18, ""SKILL: Medium""), ""Medium"", IF(REGEXMATCH(N18, ""SKILL: High""), ""High"", """")))"),"Low") -> Low | T18: =IFERROR(__xludf.DUMMYFUNCTION("IF(REGEXMATCH(N18, ""STATUS: Dev Complete - Awaiting QA""), ""Dev Complete - Awaiting QA"", IF(REGEXMATCH(N18, ""STATUS: Follow-Up Required""), ""Follow-Up Required"", IF(REGEXMATCH(N18, ""STATUS: In Progress""), ""In Progress"", IF(REGEXMATCH(N18, ""STAT"&"US: In QA""), ""In QA"", IF(REGEXMATCH(N18, ""STATUS: Needs Customer Feedback""), ""Needs Customer Feedback"", IF(REGEXMATCH(N18, ""STATUS: QA Passed - Awaiting Release""), ""QA Passed - Awaiting Release"", IF(REGEXMATCH(N18, ""STATUS: Release to Prod""),"&" ""Release to Prod"", """")))))))"),"In Progress") -> In Progress
A19: cloudwarriors-ai/automation-station | B19: Automation Station | C19: 38 | D19: Logging | E19: closed | F19: 2025-01-21T21:17:10Z | G19: =IF(I19="", "", TEXT(DATEVALUE(LEFT(F19, 10)), "dd-mmm-yyyy")) -> 21-Jan-2025 | H19: PittyG | I19: 2025-07-11T21:08:06Z | J19: =IF(I19="", "", TEXT(DATEVALUE(LEFT(I19, 10)), "dd-mmm-yyyy")) -> 11-Jul-2025 | K19: 2025-02-07T15:45:49Z | L19: =IF(K19="", "", TEXT(DATEVALUE(LEFT(K19, 10)), "dd-mmm-yyyy")) -> 07-Feb-2025 | M19: Not Specified | N19: None | P19: 0 | Q19: https://github.com/cloudwarriors-ai/automation-station/issues/38 | R19: =IFERROR(__xludf.DUMMYFUNCTION("IF(REGEXMATCH(N19, ""PRIORITY: Low""), ""Low"", IF(REGEXMATCH(N19, ""PRIORITY: Medium""), ""Medium"", IF(REGEXMATCH(N19, ""PRIORITY: High""), ""High"", """"))) "),"") | S19: =IFERROR(__xludf.DUMMYFUNCTION("IF(REGEXMATCH(N19, ""SKILL: Low""), ""Low"", IF(REGEXMATCH(N19, ""SKILL: Medium""), ""Medium"", IF(REGEXMATCH(N19, ""SKILL: High""), ""High"", """")))"),"") | T19: =IFERROR(__xludf.DUMMYFUNCTION("IF(REGEXMATCH(N19, ""STATUS: Dev Complete - Awaiting QA""), ""Dev Complete - Awaiting QA"", IF(REGEXMATCH(N19, ""STATUS: Follow-Up Required""), ""Follow-Up Required"", IF(REGEXMATCH(N19, ""STATUS: In Progress""), ""In Progress"", IF(REGEXMATCH(N19, ""STAT"&"US: In QA""), ""In QA"", IF(REGEXMATCH(N19, ""STATUS: Needs Customer Feedback""), ""Needs Customer Feedback"", IF(REGEXMATCH(N19, ""STATUS: QA Passed - Awaiting Release""), ""QA Passed - Awaiting Release"", IF(REGEXMATCH(N19, ""STATUS: Release to Prod""),"&" ""Release to Prod"", """")))))))"),"")
A20: cloudwarriors-ai/automation-station | B20: Automation Station | C20: 37 | D20: Add a send function after celery has completed a job that routes the results to the frontend | E20: closed | F20: 2025-01-21T16:37:37Z | G20: =IF(I20="", "", TEXT(DATEVALUE(LEFT(F20, 10)), "dd-mmm-yyyy")) -> 21-Jan-2025 | H20: Chaddacus | I20: 2025-07-11T21:08:07Z | J20: =IF(I20="", "", TEXT(DATEVALUE(LEFT(I20, 10)), "dd-mmm-yyyy")) -> 11-Jul-2025 | K20: 2025-02-07T15:45:49Z | L20: =IF(K20="", "", TEXT(DATEVALUE(LEFT(K20, 10)), "dd-mmm-yyyy")) -> 07-Feb-2025 | M20: Not Specified | N20: None | P20: 0 | Q20: https://github.com/cloudwarriors-ai/automation-station/issues/37 | R20: =IFERROR(__xludf.DUMMYFUNCTION("IF(REGEXMATCH(N20, ""PRIORITY: Low""), ""Low"", IF(REGEXMATCH(N20, ""PRIORITY: Medium""), ""Medium"", IF(REGEXMATCH(N20, ""PRIORITY: High""), ""High"", """"))) "),"") | S20: =IFERROR(__xludf.DUMMYFUNCTION("IF(REGEXMATCH(N20, ""SKILL: Low""), ""Low"", IF(REGEXMATCH(N20, ""SKILL: Medium""), ""Medium"", IF(REGEXMATCH(N20, ""SKILL: High""), ""High"", """")))"),"") | T20: =IFERROR(__xludf.DUMMYFUNCTION("IF(REGEXMATCH(N20, ""STATUS: Dev Complete - Awaiting QA""), ""Dev Complete - Awaiting QA"", IF(REGEXMATCH(N20, ""STATUS: Follow-Up Required""), ""Follow-Up Required"", IF(REGEXMATCH(N20, ""STATUS: In Progress""), ""In Progress"", IF(REGEXMATCH(N20, ""STAT"&"US: In QA""), ""In QA"", IF(REGEXMATCH(N20, ""STATUS: Needs Customer Feedback""), ""Needs Customer Feedback"", IF(REGEXMATCH(N20, ""STATUS: QA Passed - Awaiting Release""), ""QA Passed - Awaiting Release"", IF(REGEXMATCH(N20, ""STATUS: Release to Prod""),"&" ""Release to Prod"", """")))))))"),"")
A21: cloudwarriors-ai/automation-station | B21: Automation Station | C21: 36 | D21: Fix the CSRF Token Authentication to a True Token Authentication System | E21: open | F21: 2025-01-21T16:34:03Z | G21: =IF(I21="", "", TEXT(DATEVALUE(LEFT(F21, 10)), "dd-mmm-yyyy")) -> 21-Jan-2025 | H21: Chaddacus | I21: 2025-07-16T16:18:24Z | J21: =IF(I21="", "", TEXT(DATEVALUE(LEFT(I21, 10)), "dd-mmm-yyyy")) -> 16-Jul-2025 | L21: =IF(K21="", "", TEXT(DATEVALUE(LEFT(K21, 10)), "dd-mmm-yyyy")) | M21: Feature | N21: PRIORITY: Medium, SKILL: Medium, STATUS: In Progress | O21: Chaddacus | P21: 1 | Q21: https://github.com/cloudwarriors-ai/automation-station/issues/36 | R21: =IFERROR(__xludf.DUMMYFUNCTION("IF(REGEXMATCH(N21, ""PRIORITY: Low""), ""Low"", IF(REGEXMATCH(N21, ""PRIORITY: Medium""), ""Medium"", IF(REGEXMATCH(N21, ""PRIORITY: High""), ""High"", """"))) "),"Medium") -> Medium | S21: =IFERROR(__xludf.DUMMYFUNCTION("IF(REGEXMATCH(N21, ""SKILL: Low""), ""Low"", IF(REGEXMATCH(N21, ""SKILL: Medium""), ""Medium"", IF(REGEXMATCH(N21, ""SKILL: High""), ""High"", """")))"),"Medium") -> Medium | T21: =IFERROR(__xludf.DUMMYFUNCTION("IF(REGEXMATCH(N21, ""STATUS: Dev Complete - Awaiting QA""), ""Dev Complete - Awaiting QA"", IF(REGEXMATCH(N21, ""STATUS: Follow-Up Required""), ""Follow-Up Required"", IF(REGEXMATCH(N21, ""STATUS: In Progress""), ""In Progress"", IF(REGEXMATCH(N21, ""STAT"&"US: In QA""), ""In QA"", IF(REGEXMATCH(N21, ""STATUS: Needs Customer Feedback""), ""Needs Customer Feedback"", IF(REGEXMATCH(N21, ""STATUS: QA Passed - Awaiting Release""), ""QA Passed - Awaiting Release"", IF(REGEXMATCH(N21, ""STATUS: Release to Prod""),"&" ""Release to Prod"", """")))))))"),"In Progress") -> In Progress
A22: cloudwarriors-ai/zoom_presales_django | B22: ZoomWarriors v1 | C22: 432 | D22: [CAB] Data Cleanup Refactor - Comprehensive Reset Approach | E22: closed | F22: 2025-08-25T13:54:11Z | G22: =IF(I22="", "", TEXT(DATEVALUE(LEFT(F22, 10)), "dd-mmm-yyyy")) -> 25-Aug-2025 | H22: Matt-Keuning | I22: 2025-09-05T18:42:53Z | J22: =IF(I22="", "", TEXT(DATEVALUE(LEFT(I22, 10)), "dd-mmm-yyyy")) -> 05-Sep-2025 | K22: 2025-09-05T18:42:53Z | L22: =IF(K22="", "", TEXT(DATEVALUE(LEFT(K22, 10)), "dd-mmm-yyyy")) -> 05-Sep-2025 | M22: Not Specified | N22: None | P22: 1 | Q22: https://github.com/cloudwarriors-ai/zoom_presales_django/issues/432 | R22: =IFERROR(__xludf.DUMMYFUNCTION("IF(REGEXMATCH(N22, ""PRIORITY: Low""), ""Low"", IF(REGEXMATCH(N22, ""PRIORITY: Medium""), ""Medium"", IF(REGEXMATCH(N22, ""PRIORITY: High""), ""High"", """"))) "),"") | S22: =IFERROR(__xludf.DUMMYFUNCTION("IF(REGEXMATCH(N22, ""SKILL: Low""), ""Low"", IF(REGEXMATCH(N22, ""SKILL: Medium""), ""Medium"", IF(REGEXMATCH(N22, ""SKILL: High""), ""High"", """")))"),"") | T22: =IFERROR(__xludf.DUMMYFUNCTION("IF(REGEXMATCH(N22, ""STATUS: Dev Complete - Awaiting QA""), ""Dev Complete - Awaiting QA"", IF(REGEXMATCH(N22, ""STATUS: Follow-Up Required""), ""Follow-Up Required"", IF(REGEXMATCH(N22, ""STATUS: In Progress""), ""In Progress"", IF(REGEXMATCH(N22, ""STAT"&"US: In QA""), ""In QA"", IF(REGEXMATCH(N22, ""STATUS: Needs Customer Feedback""), ""Needs Customer Feedback"", IF(REGEXMATCH(N22, ""STATUS: QA Passed - Awaiting Release""), ""QA Passed - Awaiting Release"", IF(REGEXMATCH(N22, ""STATUS: Release to Prod""),"&" ""Release to Prod"", """")))))))"),"")
A23: cloudwarriors-ai/zoom_presales_django | B23: ZoomWarriors v1 | C23: 431 | D23: [CAB] UI Bundle Fix For CAB - Multiple UI Improvements | E23: closed | F23: 2025-08-22T18:49:09Z | G23: =IF(I23="", "", TEXT(DATEVALUE(LEFT(F23, 10)), "dd-mmm-yyyy")) -> 22-Aug-2025 | H23: Matt-Keuning | I23: 2025-09-05T18:42:39Z | J23: =IF(I23="", "", TEXT(DATEVALUE(LEFT(I23, 10)), "dd-mmm-yyyy")) -> 05-Sep-2025 | K23: 2025-09-05T18:42:39Z | L23: =IF(K23="", "", TEXT(DATEVALUE(LEFT(K23, 10)), "dd-mmm-yyyy")) -> 05-Sep-2025 | M23: Not Specified | N23: None | O23: voipin, Chaddacus, trentcharlton | P23: 1 | Q23: https://github.com/cloudwarriors-ai/zoom_presales_django/issues/431 | R23: =IFERROR(__xludf.DUMMYFUNCTION("IF(REGEXMATCH(N23, ""PRIORITY: Low""), ""Low"", IF(REGEXMATCH(N23, ""PRIORITY: Medium""), ""Medium"", IF(REGEXMATCH(N23, ""PRIORITY: High""), ""High"", """"))) "),"") | S23: =IFERROR(__xludf.DUMMYFUNCTION("IF(REGEXMATCH(N23, ""SKILL: Low""), ""Low"", IF(REGEXMATCH(N23, ""SKILL: Medium""), ""Medium"", IF(REGEXMATCH(N23, ""SKILL: High""), ""High"", """")))"),"") | T23: =IFERROR(__xludf.DUMMYFUNCTION("IF(REGEXMATCH(N23, ""STATUS: Dev Complete - Awaiting QA""), ""Dev Complete - Awaiting QA"", IF(REGEXMATCH(N23, ""STATUS: Follow-Up Required""), ""Follow-Up Required"", IF(REGEXMATCH(N23, ""STATUS: In Progress""), ""In Progress"", IF(REGEXMATCH(N23, ""STAT"&"US: In QA""), ""In QA"", IF(REGEXMATCH(N23, ""STATUS: Needs Customer Feedback""), ""Needs Customer Feedback"", IF(REGEXMATCH(N23, ""STATUS: QA Passed - Awaiting Release""), ""QA Passed - Awaiting Release"", IF(REGEXMATCH(N23, ""STATUS: Release to Prod""),"&" ""Release to Prod"", """")))))))"),"")
A24: cloudwarriors-ai/zoom_presales_django | B24: ZoomWarriors v1 | C24: 427 | D24: [CAB] zoom_presales_django – Form logic + data-cleanup fixes | E24: closed | F24: 2025-08-17T18:41:57Z | G24: =IF(I24="", "", TEXT(DATEVALUE(LEFT(F24, 10)), "dd-mmm-yyyy")) -> 17-Aug-2025 | H24: Jeffrey-Searcy | I24: 2025-09-19T03:29:21Z | J24: =IF(I24="", "", TEXT(DATEVALUE(LEFT(I24, 10)), "dd-mmm-yyyy")) -> 19-Sep-2025 | K24: 2025-09-05T18:42:30Z | L24: =IF(K24="", "", TEXT(DATEVALUE(LEFT(K24, 10)), "dd-mmm-yyyy")) -> 05-Sep-2025 | M24: Not Specified | N24: None | O24: voipin, Chaddacus, trentcharlton | P24: 1 | Q24: https://github.com/cloudwarriors-ai/zoom_presales_django/issues/427 | R24: =IFERROR(__xludf.DUMMYFUNCTION("IF(REGEXMATCH(N24, ""PRIORITY: Low""), ""Low"", IF(REGEXMATCH(N24, ""PRIORITY: Medium""), ""Medium"", IF(REGEXMATCH(N24, ""PRIORITY: High""), ""High"", """"))) "),"") | S24: =IFERROR(__xludf.DUMMYFUNCTION("IF(REGEXMATCH(N24, ""SKILL: Low""), ""Low"", IF(REGEXMATCH(N24, ""SKILL: Medium""), ""Medium"", IF(REGEXMATCH(N24, ""SKILL: High""), ""High"", """")))"),"") | T24: =IFERROR(__xludf.DUMMYFUNCTION("IF(REGEXMATCH(N24, ""STATUS: Dev Complete - Awaiting QA""), ""Dev Complete - Awaiting QA"", IF(REGEXMATCH(N24, ""STATUS: Follow-Up Required""), ""Follow-Up Required"", IF(REGEXMATCH(N24, ""STATUS: In Progress""), ""In Progress"", IF(REGEXMATCH(N24, ""STAT"&"US: In QA""), ""In QA"", IF(REGEXMATCH(N24, ""STATUS: Needs Customer Feedback""), ""Needs Customer Feedback"", IF(REGEXMATCH(N24, ""STATUS: QA Passed - Awaiting Release""), ""QA Passed - Awaiting Release"", IF(REGEXMATCH(N24, ""STATUS: Release to Prod""),"&" ""Release to Prod"", """")))))))"),"")
A25: cloudwarriors-ai/zoom_presales_django | B25: ZoomWarriors v1 | C25: 424 | D25: Zoom Phone Paging - Page Separation Appearance | E25: closed | F25: 2025-08-13T18:05:04Z | G25: =IF(I25="", "", TEXT(DATEVALUE(LEFT(F25, 10)), "dd-mmm-yyyy")) -> 13-Aug-2025 | H25: rebecca-cichy | I25: 2025-09-05T18:42:06Z | J25: =IF(I25="", "", TEXT(DATEVALUE(LEFT(I25, 10)), "dd-mmm-yyyy")) -> 05-Sep-2025 | K25: 2025-09-05T18:42:06Z | L25: =IF(K25="", "", TEXT(DATEVALUE(LEFT(K25, 10)), "dd-mmm-yyyy")) -> 05-Sep-2025 | M25: Bug | N25: PRIORITY: Low, SKILL: Low, STATUS: QA Passed - Awaiting Release | O25: Matt-Keuning | P25: 3 | Q25: https://github.com/cloudwarriors-ai/zoom_presales_django/issues/424 | R25: =IFERROR(__xludf.DUMMYFUNCTION("IF(REGEXMATCH(N25, ""PRIORITY: Low""), ""Low"", IF(REGEXMATCH(N25, ""PRIORITY: Medium""), ""Medium"", IF(REGEXMATCH(N25, ""PRIORITY: High""), ""High"", """"))) "),"Low") -> Low | S25: =IFERROR(__xludf.DUMMYFUNCTION("IF(REGEXMATCH(N25, ""SKILL: Low""), ""Low"", IF(REGEXMATCH(N25, ""SKILL: Medium""), ""Medium"", IF(REGEXMATCH(N25, ""SKILL: High""), ""High"", """")))"),"Low") -> Low | T25: =IFERROR(__xludf.DUMMYFUNCTION("IF(REGEXMATCH(N25, ""STATUS: Dev Complete - Awaiting QA""), ""Dev Complete - Awaiting QA"", IF(REGEXMATCH(N25, ""STATUS: Follow-Up Required""), ""Follow-Up Required"", IF(REGEXMATCH(N25, ""STATUS: In Progress""), ""In Progress"", IF(REGEXMATCH(N25, ""STAT"&"US: In QA""), ""In QA"", IF(REGEXMATCH(N25, ""STATUS: Needs Customer Feedback""), ""Needs Customer Feedback"", IF(REGEXMATCH(N25, ""STATUS: QA Passed - Awaiting Release""), ""QA Passed - Awaiting Release"", IF(REGEXMATCH(N25, ""STATUS: Release to Prod""),"&" ""Release to Prod"", """")))))))"),"QA Passed - Awaiting Release") -> QA Passed - Awaiting Release
A26: cloudwarriors-ai/zoom_presales_django | B26: ZoomWarriors v1 | C26: 422 | D26: Zoom Phone Harware Page - Remove Baseline Slider | E26: closed | F26: 2025-08-06T19:08:37Z | G26: =IF(I26="", "", TEXT(DATEVALUE(LEFT(F26, 10)), "dd-mmm-yyyy")) -> 06-Aug-2025 | H26: rebecca-cichy | I26: 2025-09-05T18:41:59Z | J26: =IF(I26="", "", TEXT(DATEVALUE(LEFT(I26, 10)), "dd-mmm-yyyy")) -> 05-Sep-2025 | K26: 2025-09-05T18:41:59Z | L26: =IF(K26="", "", TEXT(DATEVALUE(LEFT(K26, 10)), "dd-mmm-yyyy")) -> 05-Sep-2025 | M26: Task | N26: PRIORITY: Low, SKILL: Low, STATUS: Released to Prod | O26: Matt-Keuning | P26: 3 | Q26: https://github.com/cloudwarriors-ai/zoom_presales_django/issues/422 | R26: =IFERROR(__xludf.DUMMYFUNCTION("IF(REGEXMATCH(N26, ""PRIORITY: Low""), ""Low"", IF(REGEXMATCH(N26, ""PRIORITY: Medium""), ""Medium"", IF(REGEXMATCH(N26, ""PRIORITY: High""), ""High"", """"))) "),"Low") -> Low | S26: =IFERROR(__xludf.DUMMYFUNCTION("IF(REGEXMATCH(N26, ""SKILL: Low""), ""Low"", IF(REGEXMATCH(N26, ""SKILL: Medium""), ""Medium"", IF(REGEXMATCH(N26, ""SKILL: High""), ""High"", """")))"),"Low") -> Low | T26: =IFERROR(__xludf.DUMMYFUNCTION("IF(REGEXMATCH(N26, ""STATUS: Dev Complete - Awaiting QA""), ""Dev Complete - Awaiting QA"", IF(REGEXMATCH(N26, ""STATUS: Follow-Up Required""), ""Follow-Up Required"", IF(REGEXMATCH(N26, ""STATUS: In Progress""), ""In Progress"", IF(REGEXMATCH(N26, ""STAT"&"US: In QA""), ""In QA"", IF(REGEXMATCH(N26, ""STATUS: Needs Customer Feedback""), ""Needs Customer Feedback"", IF(REGEXMATCH(N26, ""STATUS: QA Passed - Awaiting Release""), ""QA Passed - Awaiting Release"", IF(REGEXMATCH(N26, ""STATUS: Release to Prod""),"&" ""Release to Prod"", """")))))))"),"")
A27: cloudwarriors-ai/zoom_presales_django | B27: ZoomWarriors v1 | C27: 418 | D27: Edit Previous Customer Quote Functionality - Saving Previously Entered Data | E27: closed | F27: 2025-08-05T16:40:25Z | G27: =IF(I27="", "", TEXT(DATEVALUE(LEFT(F27, 10)), "dd-mmm-yyyy")) -> 05-Aug-2025 | H27: rebecca-cichy | I27: 2025-09-05T18:41:50Z | J27: =IF(I27="", "", TEXT(DATEVALUE(LEFT(I27, 10)), "dd-mmm-yyyy")) -> 05-Sep-2025 | K27: 2025-09-05T18:41:50Z | L27: =IF(K27="", "", TEXT(DATEVALUE(LEFT(K27, 10)), "dd-mmm-yyyy")) -> 05-Sep-2025 | M27: Bug | N27: PRIORITY: High, SKILL: Medium, STATUS: Released to Prod | O27: Matt-Keuning | P27: 4 | Q27: https://github.com/cloudwarriors-ai/zoom_presales_django/issues/418 | R27: =IFERROR(__xludf.DUMMYFUNCTION("IF(REGEXMATCH(N27, ""PRIORITY: Low""), ""Low"", IF(REGEXMATCH(N27, ""PRIORITY: Medium""), ""Medium"", IF(REGEXMATCH(N27, ""PRIORITY: High""), ""High"", """"))) "),"High") -> High | S27: =IFERROR(__xludf.DUMMYFUNCTION("IF(REGEXMATCH(N27, ""SKILL: Low""), ""Low"", IF(REGEXMATCH(N27, ""SKILL: Medium""), ""Medium"", IF(REGEXMATCH(N27, ""SKILL: High""), ""High"", """")))"),"Medium") -> Medium | T27: =IFERROR(__xludf.DUMMYFUNCTION("IF(REGEXMATCH(N27, ""STATUS: Dev Complete - Awaiting QA""), ""Dev Complete - Awaiting QA"", IF(REGEXMATCH(N27, ""STATUS: Follow-Up Required""), ""Follow-Up Required"", IF(REGEXMATCH(N27, ""STATUS: In Progress""), ""In Progress"", IF(REGEXMATCH(N27, ""STAT"&"US: In QA""), ""In QA"", IF(REGEXMATCH(N27, ""STATUS: Needs Customer Feedback""), ""Needs Customer Feedback"", IF(REGEXMATCH(N27, ""STATUS: QA Passed - Awaiting Release""), ""QA Passed - Awaiting Release"", IF(REGEXMATCH(N27, ""STATUS: Release to Prod""),"&" ""Release to Prod"", """")))))))"),"")
